{
  "comments": [
    {
      "key": {
        "uuid": "22e8aff3_adaa86f9",
        "filename": "zvmsdk/database.py",
        "patchSetId": 1
      },
      "lineNbr": 378,
      "author": {
        "id": 1008926
      },
      "writtenOn": "2017-09-28T07:08:20Z",
      "side": 1,
      "message": "same to other module,  can remove this exception, no need to check the existence for delete.",
      "range": {
        "startLine": 378,
        "startChar": 50,
        "endLine": 378,
        "endChar": 51
      },
      "revId": "5d00aba6cbfc179e6e639ebfb15d2793bde1a4de",
      "serverId": "d5d70762-12d0-45a1-890d-524b12d3f735",
      "unresolved": false
    }
  ]
}